2024-10-05 20:48:42,521 - api - INFO - Using device: cuda
2024-10-05 20:48:42,685 - api - INFO - All models and scalers loaded successfully
2024-10-05 20:49:00,536 - api - INFO - PINN processing completed. Shape of denoised_data: (100,)
2024-10-05 20:49:00,542 - api - INFO - GAN processing completed. Shape of generated_samples: (10, 100)
2024-10-05 20:49:00,543 - api - INFO - Augmented data prepared. Shape: (11, 100)
2024-10-05 20:49:00,543 - api - INFO - Shape of augmented_data after reshaping: (11, 100)
2024-10-05 20:49:00,544 - api - INFO - Shape of vae_input: torch.Size([11, 100])
2024-10-05 20:49:00,544 - api - WARNING - Mismatch between VAE input_dim (50) and data shape (100)
2024-10-05 20:49:00,549 - api - INFO - Adjusted vae_input shape: torch.Size([11, 50])
2024-10-05 20:49:00,549 - root - INFO - Batch 0: Input data shape: torch.Size([])
2024-10-05 20:49:00,549 - root - INFO - Batch 0: Reshaped data shape: torch.Size([])
2024-10-05 20:49:00,550 - root - ERROR - Error processing batch 0: tuple index out of range
2024-10-05 20:49:00,550 - api - ERROR - Error in VAE processing: tuple index out of range
2024-10-05 20:49:00,551 - api - ERROR - Traceback (most recent call last):
  File "E:\nasa_space_hack24\api.py", line 183, in process_seismic_data_task
    anomalies, original_data, reconstructed_data = detect_anomalies(vae_model, vae_input, device, vae_scaler)
                                                   ^^^^^^^^^^^^^^^^^^^^^^^^^^^^^^^^^^^^^^^^^^^^^^^^^^^^^^^^^^
  File "E:\nasa_space_hack24\vaee\train.py", line 94, in detect_anomalies
    if data.shape[1] != vae.input_dim:
       ~~~~~~~~~~^^^
IndexError: tuple index out of range

2024-10-05 20:49:00,551 - api - ERROR - Unexpected error processing seismic data: Error in VAE processing: tuple index out of range
2024-10-05 20:49:00,552 - api - ERROR - Traceback (most recent call last):
  File "E:\nasa_space_hack24\api.py", line 183, in process_seismic_data_task
    anomalies, original_data, reconstructed_data = detect_anomalies(vae_model, vae_input, device, vae_scaler)
                                                   ^^^^^^^^^^^^^^^^^^^^^^^^^^^^^^^^^^^^^^^^^^^^^^^^^^^^^^^^^^
  File "E:\nasa_space_hack24\vaee\train.py", line 94, in detect_anomalies
    if data.shape[1] != vae.input_dim:
       ~~~~~~~~~~^^^
IndexError: tuple index out of range

During handling of the above exception, another exception occurred:

Traceback (most recent call last):
  File "E:\nasa_space_hack24\api.py", line 189, in process_seismic_data_task
    raise ValueError(f"Error in VAE processing: {str(e)}")
ValueError: Error in VAE processing: tuple index out of range

2024-10-05 20:49:00,554 - api - ERROR - Error in process_seismic_file endpoint: Unexpected error: Error in VAE processing: tuple index out of range
